The above exception was the direct cause of the following exception:

Traceback (most recent call last):
  File "/home/runner/workspace/.pythonlibs/lib/python3.10/site-packages/django/core/handlers/exception.py", line 55, in inner
    response = get_response(request)
  File "/home/runner/workspace/.pythonlibs/lib/python3.10/site-packages/django/core/handlers/base.py", line 197, in _get_response
    response = wrapped_callback(request, *callback_args, **callback_kwargs)
  File "/home/runner/workspace/.pythonlibs/lib/python3.10/site-packages/django/contrib/auth/decorators.py", line 23, in _wrapper_view
    return view_func(request, *args, **kwargs)
  File "/home/runner/workspace/core/views/views.py", line 244, in documents
    return render(request, 'home/documents.html', {'documents': documents})
  File "/home/runner/workspace/.pythonlibs/lib/python3.10/site-packages/django/shortcuts.py", line 24, in render
    content = loader.render_to_string(template_name, context, request, using=using)
  File "/home/runner/workspace/.pythonlibs/lib/python3.10/site-packages/django/template/loader.py", line 62, in render_to_string
    return template.render(context, request)
  File "/home/runner/workspace/.pythonlibs/lib/python3.10/site-packages/django/template/backends/django.py", line 61, in render
    return self.template.render(context)
  File "/home/runner/workspace/.pythonlibs/lib/python3.10/site-packages/django/template/base.py", line 171, in render
    return self._render(context)
  File "/home/runner/workspace/.pythonlibs/lib/python3.10/site-packages/django/template/base.py", line 163, in _render
    return self.nodelist.render(context)
  File "/home/runner/workspace/.pythonlibs/lib/python3.10/site-packages/django/template/base.py", line 1000, in render
    return SafeString("".join([node.render_annotated(context) for node in self]))
  File "/home/runner/workspace/.pythonlibs/lib/python3.10/site-packages/django/template/base.py", line 1000, in <listcomp>
    return SafeString("".join([node.render_annotated(context) for node in self]))
  File "/home/runner/workspace/.pythonlibs/lib/python3.10/site-packages/django/template/base.py", line 961, in render_annotated
    return self.render(context)
  File "/home/runner/workspace/.pythonlibs/lib/python3.10/site-packages/django/template/loader_tags.py", line 159, in render
    return compiled_parent._render(context)
  File "/home/runner/workspace/.pythonlibs/lib/python3.10/site-packages/django/template/base.py", line 163, in _render
    return self.nodelist.render(context)
  File "/home/runner/workspace/.pythonlibs/lib/python3.10/site-packages/django/template/base.py", line 1000, in render
    return SafeString("".join([node.render_annotated(context) for node in self]))
  File "/home/runner/workspace/.pythonlibs/lib/python3.10/site-packages/django/template/base.py", line 1000, in <listcomp>
    return SafeString("".join([node.render_annotated(context) for node in self]))
  File "/home/runner/workspace/.pythonlibs/lib/python3.10/site-packages/django/template/base.py", line 961, in render_annotated
    return self.render(context)
  File "/home/runner/workspace/.pythonlibs/lib/python3.10/site-packages/django/template/loader_tags.py", line 65, in render
    result = block.nodelist.render(context)
  File "/home/runner/workspace/.pythonlibs/lib/python3.10/site-packages/django/template/base.py", line 1000, in render
    return SafeString("".join([node.render_annotated(context) for node in self]))
  File "/home/runner/workspace/.pythonlibs/lib/python3.10/site-packages/django/template/base.py", line 1000, in <listcomp>
    return SafeString("".join([node.render_annotated(context) for node in self]))
  File "/home/runner/workspace/.pythonlibs/lib/python3.10/site-packages/django/template/base.py", line 961, in render_annotated
    return self.render(context)
  File "/home/runner/workspace/.pythonlibs/lib/python3.10/site-packages/django/template/defaulttags.py", line 324, in render
    if match:
  File "/home/runner/workspace/.pythonlibs/lib/python3.10/site-packages/django/db/models/query.py", line 412, in __bool__
    self._fetch_all()
  File "/home/runner/workspace/.pythonlibs/lib/python3.10/site-packages/django/db/models/query.py", line 1926, in _fetch_all
    self._result_cache = list(self._iterable_class(self))
  File "/home/runner/workspace/.pythonlibs/lib/python3.10/site-packages/django/db/models/query.py", line 91, in __iter__
    results = compiler.execute_sql(
  File "/home/runner/workspace/.pythonlibs/lib/python3.10/site-packages/django/db/models/sql/compiler.py", line 1562, in execute_sql
    cursor.execute(sql, params)
  File "/home/runner/workspace/.pythonlibs/lib/python3.10/site-packages/django/db/backends/utils.py", line 122, in execute
    return super().execute(sql, params)
  File "/home/runner/workspace/.pythonlibs/lib/python3.10/site-packages/django/db/backends/utils.py", line 79, in execute
    return self._execute_with_wrappers(
  File "/home/runner/workspace/.pythonlibs/lib/python3.10/site-packages/django/db/backends/utils.py", line 92, in _execute_with_wrappers
    return executor(sql, params, many, context)
  File "/home/runner/workspace/.pythonlibs/lib/python3.10/site-packages/django/db/backends/utils.py", line 100, in _execute
    with self.db.wrap_database_errors:
  File "/home/runner/workspace/.pythonlibs/lib/python3.10/site-packages/django/db/utils.py", line 91, in __exit__
    raise dj_exc_value.with_traceback(traceback) from exc_value
  File "/home/runner/workspace/.pythonlibs/lib/python3.10/site-packages/django/db/backends/utils.py", line 105, in _execute
    return self.cursor.execute(sql, params)
  File "/home/runner/workspace/.pythonlibs/lib/python3.10/site-packages/psycopg/cursor.py", line 732, in execute
    raise ex.with_traceback(None)
django.db.utils.ProgrammingError: relation "core_document" does not exist
LINE 1: ...ument"."description", "core_document"."file" FROM "core_docu...