Exception in thread django-main-thread:
Traceback (most recent call last):
  File "/nix/store/qlb1pg370bb647nj4dhc81y2jszvciz7-python3-3.10.16/lib/python3.10/threading.py", line 1016, in _bootstrap_inner
    self.run()
  File "/nix/store/qlb1pg370bb647nj4dhc81y2jszvciz7-python3-3.10.16/lib/python3.10/threading.py", line 953, in run
    self._target(*self._args, **self._kwargs)
  File "/home/runner/workspace/.pythonlibs/lib/python3.10/site-packages/django/utils/autoreload.py", line 64, in wrapper
    fn(*args, **kwargs)
  File "/home/runner/workspace/.pythonlibs/lib/python3.10/site-packages/django/core/management/commands/runserver.py", line 133, in inner_run
    self.check(display_num_errors=True)
  File "/home/runner/workspace/.pythonlibs/lib/python3.10/site-packages/django/core/management/base.py", line 485, in check
    all_issues = checks.run_checks(
  File "/home/runner/workspace/.pythonlibs/lib/python3.10/site-packages/django/core/checks/registry.py", line 88, in run_checks
    new_errors = check(app_configs=app_configs, databases=databases)
  File "/home/runner/workspace/.pythonlibs/lib/python3.10/site-packages/django/core/checks/urls.py", line 42, in check_url_namespaces_unique
    all_namespaces = _load_all_namespaces(resolver)
  File "/home/runner/workspace/.pythonlibs/lib/python3.10/site-packages/django/core/checks/urls.py", line 61, in _load_all_namespaces
    url_patterns = getattr(resolver, "url_patterns", [])
  File "/home/runner/workspace/.pythonlibs/lib/python3.10/site-packages/django/utils/functional.py", line 47, in __get__
    res = instance.__dict__[self.name] = self.func(instance)
  File "/home/runner/workspace/.pythonlibs/lib/python3.10/site-packages/django/urls/resolvers.py", line 735, in url_patterns
    patterns = getattr(self.urlconf_module, "urlpatterns", self.urlconf_module)
  File "/home/runner/workspace/.pythonlibs/lib/python3.10/site-packages/django/utils/functional.py", line 47, in __get__
    res = instance.__dict__[self.name] = self.func(instance)
  File "/home/runner/workspace/.pythonlibs/lib/python3.10/site-packages/django/urls/resolvers.py", line 728, in urlconf_module
    return import_module(self.urlconf_name)
  File "/nix/store/qlb1pg370bb647nj4dhc81y2jszvciz7-python3-3.10.16/lib/python3.10/importlib/__init__.py", line 126, in import_module
    return _bootstrap._gcd_import(name[level:], package, level)
  File "<frozen importlib._bootstrap>", line 1050, in _gcd_import
  File "<frozen importlib._bootstrap>", line 1027, in _find_and_load
  File "<frozen importlib._bootstrap>", line 1006, in _find_and_load_unlocked
  File "<frozen importlib._bootstrap>", line 688, in _load_unlocked
  File "<frozen importlib._bootstrap_external>", line 883, in exec_module
  File "<frozen importlib._bootstrap>", line 241, in _call_with_frames_removed
  File "/home/runner/workspace/bildungsplattform/urls.py", line 22, in <module>
    path('', include('core.urls')),
  File "/home/runner/workspace/.pythonlibs/lib/python3.10/site-packages/django/urls/conf.py", line 38, in include
    urlconf_module = import_module(urlconf_module)
  File "/nix/store/qlb1pg370bb647nj4dhc81y2jszvciz7-python3-3.10.16/lib/python3.10/importlib/__init__.py", line 126, in import_module
    return _bootstrap._gcd_import(name[level:], package, level)
  File "<frozen importlib._bootstrap>", line 1050, in _gcd_import
  File "<frozen importlib._bootstrap>", line 1027, in _find_and_load
  File "<frozen importlib._bootstrap>", line 1006, in _find_and_load_unlocked
  File "<frozen importlib._bootstrap>", line 688, in _load_unlocked
  File "<frozen importlib._bootstrap_external>", line 883, in exec_module
  File "<frozen importlib._bootstrap>", line 241, in _call_with_frames_removed
  File "/home/runner/workspace/core/urls.py", line 2, in <module>
    from .views import views, checkout_view, orders_view
  File "/home/runner/workspace/core/views/views.py", line 187
    @login_required
    ^