Exception in thread django-main-thread:
Traceback (most recent call last):
  File "/nix/store/qlb1pg370bb647nj4dhc81y2jszvciz7-python3-3.10.16/lib/python3.10/threading.py", line 1016, in _bootstrap_inner
    self.run()
  File "/nix/store/qlb1pg370bb647nj4dhc81y2jszvciz7-python3-3.10.16/lib/python3.10/threading.py", line 953, in run
    self._target(*self._args, **self._kwargs)
  File "/home/runner/workspace/.pythonlibs/lib/python3.10/site-packages/django/utils/autoreload.py", line 64, in wrapper
    fn(*args, **kwargs)
  File "/home/runner/workspace/.pythonlibs/lib/python3.10/site-packages/django/core/management/commands/runserver.py", line 137, in inner_run
    self.check_migrations()
  File "/home/runner/workspace/.pythonlibs/lib/python3.10/site-packages/django/core/management/base.py", line 587, in check_migrations
    executor = MigrationExecutor(connections[DEFAULT_DB_ALIAS])
  File "/home/runner/workspace/.pythonlibs/lib/python3.10/site-packages/django/db/migrations/executor.py", line 18, in __init__
    self.loader = MigrationLoader(self.connection)
  File "/home/runner/workspace/.pythonlibs/lib/python3.10/site-packages/django/db/migrations/loader.py", line 58, in __init__
    self.build_graph()
  File "/home/runner/workspace/.pythonlibs/lib/python3.10/site-packages/django/db/migrations/loader.py", line 229, in build_graph
    self.load_disk()
  File "/home/runner/workspace/.pythonlibs/lib/python3.10/site-packages/django/db/migrations/loader.py", line 120, in load_disk
    migration_module = import_module(migration_path)
  File "/nix/store/qlb1pg370bb647nj4dhc81y2jszvciz7-python3-3.10.16/lib/python3.10/importlib/__init__.py", line 126, in import_module
    return _bootstrap._gcd_import(name[level:], package, level)
  File "<frozen importlib._bootstrap>", line 1050, in _gcd_import
  File "<frozen importlib._bootstrap>", line 1027, in _find_and_load
  File "<frozen importlib._bootstrap>", line 1006, in _find_and_load_unlocked
  File "<frozen importlib._bootstrap>", line 688, in _load_unlocked
  File "<frozen importlib._bootstrap_external>", line 883, in exec_module
  File "<frozen importlib._bootstrap>", line 241, in _call_with_frames_removed
  File "/home/runner/workspace/core/migrations/0040_alter_document_file.py", line 7, in <module>
    class Migration(migrations.Migration):
  File "/home/runner/workspace/core/migrations/0040_alter_document_file.py", line 17, in Migration
    field=models.FileField(storage=core.storage.ReplitObjectStorage, upload_to=''),
AttributeError: module 'core.storage' has no attribute 'ReplitObjectStorage'. Did you mean: 'ScalewayObjectStorage'?